<?xml version="1.0" encoding="UTF-8"?>
<!-- Generated by org.testng.reporters.JUnitXMLReporter -->
<testsuite hostname="YP1007518DT" name="Vtiger Automation" tests="3" failures="3" timestamp="5 Feb 2019 14:38:26 GMT" time="0.042" errors="0">
  <testcase name="verifyToLogin" time="0.017" classname="testCases.Login_TestCase">
    <failure type="java.lang.NullPointerException">
      <![CDATA[java.lang.NullPointerException
	at testActions.Login_POF.loginApplication(Login_POF.java:17)
	at testCases.Login_TestCase.verifyToLogin(Login_TestCase.java:13)
	at java.util.concurrent.ThreadPoolExecutor.runWorker(Unknown Source)
	at java.util.concurrent.ThreadPoolExecutor$Worker.run(Unknown Source)
	at java.lang.Thread.run(Unknown Source)
... Removed 10 stack frames]]>
    </failure>
  </testcase> <!-- verifyToLogin -->
  <testcase name="verifyToLogin" time="0.021" classname="testCases.SignIn_TestCase">
    <failure type="java.lang.NullPointerException">
      <![CDATA[java.lang.NullPointerException
	at testActions.SignIn_POF.signIn(SignIn_POF.java:14)
	at testCases.SignIn_TestCase.verifyToLogin(SignIn_TestCase.java:17)
	at java.util.concurrent.ThreadPoolExecutor.runWorker(Unknown Source)
	at java.util.concurrent.ThreadPoolExecutor$Worker.run(Unknown Source)
	at java.lang.Thread.run(Unknown Source)
... Removed 10 stack frames]]>
    </failure>
  </testcase> <!-- verifyToLogin -->
  <testcase name="verifyToLogin" time="0.021" classname="testCases.LogOut_TestCase">
    <failure type="java.lang.NullPointerException">
      <![CDATA[java.lang.NullPointerException
	at testActions.LogOut_POF.logout(LogOut_POF.java:13)
	at testCases.LogOut_TestCase.verifyToLogin(LogOut_TestCase.java:14)
	at java.util.concurrent.ThreadPoolExecutor.runWorker(Unknown Source)
	at java.util.concurrent.ThreadPoolExecutor$Worker.run(Unknown Source)
	at java.lang.Thread.run(Unknown Source)
... Removed 10 stack frames]]>
    </failure>
  </testcase> <!-- verifyToLogin -->
</testsuite> <!-- Vtiger Automation -->
